Workbook

Sheet 全期間集計_TOTAL
A3: 項目名 | B3: 全期間合計
A4: 登録人数 | B4: ='202512'!B4+'202601'!B4 -> 8237
A5: ログインユーザー数 | B5: ='202512'!B5+'202601'!B5 -> 5858
A6: SMS認証 | B6: ='202512'!B6+'202601'!B6 -> 8206
A7: 登録に対してSMS認証割合 | B7: =B6/B4 -> 0.99623649
A8: 入金不要ボーナス使用済ユーザー数 | B8: ='202512'!B8+'202601'!B8 -> 7765
A9: 登録に対してNDB使用割合 | B9: =B8/B4 -> 0.94269758
A10: FTDのみ入金者数 | B10: ='202512'!B10+'202601'!B10 -> 579
A11: 登録に対してFTDのみの割合 | B11: =B10/B4 -> 0.070292582
A12: 2nd入金のみユーザー数 | B12: ='202512'!B12+'202601'!B12 -> 111
A13: 登録に対して2nd使用割合 | B13: =B12/B4 -> 0.01347578
A14: 3nd入金のみユーザー数 | B14: ='202512'!B14+'202601'!B14 -> 74
A15: 登録に対して3nd使用割合 | B15: =B14/B4 -> 0.0089838533
A16: 4nd入金以降ユーザー数 | B16: ='202512'!B16+'202601'!B16 -> 207
A17: 登録に対して4nd使用割合 | B17: =B16/B4 -> 0.025130509
A18: 今月登録のFTD以降ユーザー数 | B18: ='202512'!B18+'202601'!B18 -> 1312
A19: 今月登録FTD以降ユーザー割合 | B19: =B18/B4 -> 0.15928129
A20: 今月登録のアクティブユーザー数 | B20: ='202512'!B20+'202601'!B20 -> 1366
A21: 前月登録のアクティブユーザー数 | B21: ='202512'!B21+'202601'!B21 -> 743
A22: 前々月登録のアクティブユーザー数 | B22: ='202512'!B22+'202601'!B22 -> #VALUE!
A23: 3か月以上アクティブプレイヤー数 | B23: ='202512'!B23+'202601'!B23 -> #VALUE!
A24: 総入金回数 | B24: ='202512'!B24+'202601'!B24 -> 12432
A25: 入金者数(デイリーユニーク) | B25: ='202512'!B25+'202601'!B25 -> 3776
A26: アクティブプレイ人数（ユニーク） | B26: ='202512'!B26+'202601'!B26 -> 2137
A27: 総入金額 / Total DP amt | B27: ='202512'!B27+'202601'!B27 -> 196091868
A28: 平均入金額(一回の入金額) / Ave amt per DP | B28: =B27/B24 -> 15773.155
A29: 平均入金額(ユニークユーザー) / Ave DP amt (Unique user) | B29: =B27/B26 -> 91760.35
A30: 総出金回数 | B30: ='202512'!B30+'202601'!B30 -> 2744
A31: 総出金人数 | B31: ='202512'!B31+'202601'!B31 -> 1971
A32: 総出金額 / Total WD amt | B32: ='202512'!B32+'202601'!B32 -> 142781785
A33: 入金額に対して出金割合 | B33: =B32/B27 -> 0.72813721
A34: T/O(リアルのみ) / Total real bet | B34: ='202512'!B34+'202601'!B34 -> 3153510256
A35: T/O率(リアルのみ) / Total real bet ratio | B35: ='202512'!B35+'202601'!B35 -> 32.519293
A36: T/O(ボーナス+リアルマネーの合計) / Total bet (Real+Bonus) | B36: ='202512'!B36+'202601'!B36 -> 3153510256
A37: 勝利金(リアルのみ) / Winning amt (Real) | B37: ='202512'!B37+'202601'!B37 -> 3047926570
A38: 勝利金(ボーナスのみ) / Winning amt (Bonus) | B38: ='202512'!B38+'202601'!B38 -> 1242834.8
A39: 勝利金(ボーナス+リアルマネーの合計) / Winning (Bonus+Real) | B39: ='202512'!B39+'202601'!B39 -> 3049169405
A40: リアルマネー残高 / Real Money Balance | B40: ='202512'!B40+'202601'!B40 -> 18591291
A41: ボーナス・マネー残高 / Bonus Money Balance | B41: ='202512'!B41+'202601'!B41 -> 2084881
A42: RTP | B42: =('202512'!B42+'202601'!B42)/2 -> 0.96709261
...

Sheet ダッシュボード
A1: スロット天国 KPI ダッシュボード
A3: 【全体サマリー（全期間合計）】
A4: 総登録人数 | B4: ='202511'!B4+'202512'!B4+'202601'!B4 -> 8537
A5: 総FTD数 | B5: ='202511'!B10+'202512'!B10+'202601'!B10 -> 587
A6: 総入金額 | B6: ='202511'!B23+'202512'!B27+'202601'!B27 -> 196678014
A7: 総出金額 | B7: ='202511'!B28+'202512'!B32+'202601'!B32 -> 143310248
A8: 入出金差分 | B8: =B6-B7 -> 53367766
A9: 総GGR | B9: ='202511'!B41+'202512'!B45+'202601'!B45 -> 1.0440442e+08
A10: 総NGR | B10: ='202511'!B56+'202512'!B64+'202601'!B64 -> 47205265
A11: 平均RTP | B11: =AVERAGE('202511'!C38,'202512'!C42,'202601'!C42) -> 0.96343727
A13: 【月次KPI比較】
A14: 指標 | B14: 2025/11 | C14: 2025/12 | D14: 2026/01 | E14: 合計/平均
A15: 登録人数 | B15: ='202511'!B4 -> 300 | C15: ='202512'!B4 -> 2552 | D15: ='202601'!B4 -> 5685 | E15: =SUM(B15:D15) -> 8537
A16: SMS認証 | B16: ='202511'!B6 -> 166 | C16: ='202512'!B6 -> 2521 | D16: ='202601'!B6 -> 5685 | E16: =SUM(B16:D16) -> 8372
A17: FTD数 | B17: ='202511'!B10 -> 8 | C17: ='202512'!B10 -> 231 | D17: ='202601'!B10 -> 348 | E17: =SUM(B17:D17) -> 587
A18: 入金者数(ユニーク) | B18: ='202511'!B21 -> 32 | C18: ='202512'!B25 -> 2234 | D18: ='202601'!B25 -> 1542 | E18: =SUM(B18:D18) -> 3808
A19: アクティブプレイ人数 | B19: ='202511'!B22 -> 84 | C19: ='202512'!B26 -> 798 | D19: ='202601'!B26 -> 1339 | E19: =SUM(B19:D19) -> 2221
A20: 総入金額 | B20: ='202511'!B23 -> 586146 | C20: ='202512'!B27 -> 66633871 | D20: ='202601'!B27 -> 129457997 | E20: =SUM(B20:D20) -> 196678014
A21: 総出金額 | B21: ='202511'!B28 -> 528463 | C21: ='202512'!B32 -> 48341793 | D21: ='202601'!B32 -> 94439992 | E21: =SUM(B21:D21) -> 143310248
A22: 入出金差分 | B22: ='202511'!B23-'202511'!B28 -> 57683 | C22: ='202512'!B27-'202512'!B32 -> 18292078 | D22: ='202601'!B27-'202601'!B32 -> 35018005 | E22: =SUM(B22:D22) -> 53367766
A23: T/O(合計) | B23: ='202511'!B32 -> 5043994.2 | C23: ='202512'!B36 -> 1120432234 | D23: ='202601'!B36 -> 2033078021 | E23: =SUM(B23:D23) -> 3158554250
A24: 勝利金(合計) | B24: ='202511'!B35 -> 4980421.4 | C24: ='202512'!B39 -> 1084888258 | D24: ='202601'!B39 -> 1964281147 | E24: =SUM(B24:D24) -> 3054149826
A25: RTP | B25: ='202511'!C38 -> 0.95612659 | C25: ='202512'!C42 -> 0.96604376 | D25: ='202601'!C42 -> 0.96814145 | E25: =AVERAGE(B25:D25) -> 0.96343727
A26: GGR | B26: ='202511'!B41 -> 63572.8 | C26: ='202512'!B45 -> 35543976 | D26: ='202601'!B45 -> 68796875 | E26: =SUM(B26:D26) -> 1.0440442e+08
A27: NGR | B27: ='202511'!B56 -> -4802217.4 | C27: ='202512'!B64 -> 15958869 | D27: ='202601'!B64 -> 36048614 | E27: =SUM(B27:D27) -> 47205265
A30: 【ゲーム別GGR（2025/12）】
A31: ゲーム種別 | B31: GGR | C31: NGR | D31: 割合
A32: パチンコ | B32: ='202512'!B128 -> 4373745.1 | C32: ='202512'!B130 -> 4373745.1 | D32: =IFERROR(B32/SUM($B$32:$B$35),0) -> 0.1487952
A33: パチスロ | B33: ='202512'!B147 -> 3186351.8 | C33: ='202512'!B149 -> 3186351.8 | D33: =IFERROR(B33/SUM($B$32:$B$35),0) -> 0.10839997
A34: スロット | B34: ='202512'!B166 -> 17254981 | C34: ='202512'!B168 -> 17254981 | D34: =IFERROR(B34/SUM($B$32:$B$35),0) -> 0.58701601
A35: ライブ | B35: ='202512'!B185 -> 4579318.2 | C35: ='202512'!B187 -> 4579318.2 | D35: =IFERROR(B35/SUM($B$32:$B$35),0) -> 0.15578882
A36: 合計 | B36: =SUM(B32:B35) -> 29394396 | C36: =SUM(C32:C35) -> 29394396 | D36: 100%
A39: 【入出金手段別内訳（2025/12）】
A40: 入金手段 | B40: 金額 | C40: 件数 | D40: 割合
A41: 銀行（自動） | B41: ='202512'!B194 -> 15576600 | C41: ='202512'!C194 -> 164 | D41: =IFERROR(B41/SUM($B$41:$B$45),0) -> 0.233764
A42: 仮想通貨 | B42: ='202512'!B195 -> 7849442 | C42: ='202512'!C195 -> 312 | D42: =IFERROR(B42/SUM($B$41:$B$45),0) -> 0.11779958
A43: 銀行（手動） | B43: ='202512'!B196 -> 8729186 | C43: ='202512'!C196 -> 519 | D43: =IFERROR(B43/SUM($B$41:$B$45),0) -> 0.13100223
A44: EC(コンビニ) | B44: ='202512'!B197 -> 1121000 | C44: ='202512'!C197 -> 36 | D44: =IFERROR(B44/SUM($B$41:$B$45),0) -> 0.016823276
A45: PayPay | B45: ='202512'!B198 -> 33357643 | C45: ='202512'!C198 -> 2660 | D45: =IFERROR(B45/SUM($B$41:$B$45),0) -> 0.50061091
A46: 入金合計 | B46: =SUM(B41:B45) -> 66633871 | C46: =SUM(C41:C45) -> 3691 | D46: 100%
...

Sheet 202511
A1: 項目名 | B1: 月次合計 | C1: 日次平均 | D1: 11/27 | E1: 11/28 | F1: 11/29 | G1: 11/30
D2: 木 | E2: 金 | F2: 土 | G2: 日
A3: 全体KPI | B3: =SUM(D3:G3) -> 0
A4: 登録人数 | B4: =SUM(D4:G4) -> 300 | C4: =AVERAGE(D4:G4) -> 75 | D4: =171-10 -> 161 | E4: 50 | F4: 41 | G4: 48
A5: ログインユーザー数 | B5: =SUM(D5:G5) -> 193 | C5: =AVERAGE(D5:G5) -> 48.25 | D5: 92 | E5: 46 | F5: 31 | G5: 24
A6: SMS認証 | B6: =SUM(D6:G6) -> 166 | C6: =AVERAGE(D6:G6) -> 41.5 | D6: 89 | E6: 27 | F6: 32 | G6: 18
A7: 登録に対してSMS認証割合 | B7: =SUM(D7:G7) -> 2.2482828 | C7: =AVERAGE(D7:G7) -> 0.56207071 | D7: =IFERROR(D6/D4,0) -> 0.55279503 | E7: =IFERROR(E6/E4,0) -> 0.54 | F7: =IFERROR(F6/F4,0) -> 0.7804878 | G7: =IFERROR(G6/G4,0) -> 0.375
A8: 入金不要ボーナス使用済ユーザー数 | B8: =SUM(D8:G8) -> 0 | C8: =AVERAGE(D8:G8) -> 0 | D8: 0 | E8: 0 | F8: 0 | G8: 0
A9: 登録に対してNDB使用割合 | B9: =SUM(D9:G9) -> 0 | C9: =AVERAGE(D9:G9) -> 0 | D9: =D8/D4 -> 0 | E9: =E8/E4 -> 0 | F9: =F8/F4 -> 0 | G9: =G8/G4 -> 0
A10: FTD数 | B10: =SUM(D10:G10) -> 8 | C10: =AVERAGE(D10:G10) -> 2 | D10: 7 | E10: 1 | F10: 0 | G10: 0
A11: 登録に対して1st使用割合 | B11: =SUM(D11:G11) -> 0.063478261 | C11: =AVERAGE(D11:G11) -> 0.015869565 | D11: =D10/D4 -> 0.043478261 | E11: =E10/E4 -> 0.02 | F11: =F10/F4 -> 0 | G11: =G10/G4 -> 0
A12: 2nd入金以降ユーザー数 | B12: =SUM(D12:G12) -> 10 | C12: =AVERAGE(D12:G12) -> 2.5 | D12: 6 | E12: 1 | F12: 0 | G12: 3
A13: 登録に対して2nd使用割合 | B13: =SUM(D13:G13) -> 0.11976708 | C13: =AVERAGE(D13:G13) -> 0.02994177 | D13: =D12/D4 -> 0.037267081 | E13: =E12/E4 -> 0.02 | F13: =F12/F4 -> 0 | G13: =G12/G4 -> 0.0625
A14: 3nd入金以降ユーザー数 | B14: =SUM(D14:G14) -> 3 | C14: =AVERAGE(D14:G14) -> 0.75 | D14: 3 | E14: 0 | F14: 0 | G14: 0
A15: 登録に対して3nd使用割合 | B15: =SUM(D15:G15) -> 0.01863354 | C15: =AVERAGE(D15:G15) -> 0.0046583851 | D15: =D14/D4 -> 0.01863354 | E15: =E14/E4 -> 0 | F15: =F14/F4 -> 0 | G15: =G14/G4 -> 0
A16: 4nd入金以降ユーザー数 | B16: =SUM(D16:G16) -> 21 | C16: =AVERAGE(D16:G16) -> 5.25 | D16: 6 | E16: 4 | F16: 5 | G16: 6
A17: 登録に対して4nd使用割合 | B17: =SUM(D17:G17) -> 0.3642183 | C17: =AVERAGE(D17:G17) -> 0.091054575 | D17: =D16/D4 -> 0.037267081 | E17: =E16/E4 -> 0.08 | F17: =F16/F4 -> 0.12195122 | G17: =G16/G4 -> 0.125
A18: 今月登録のFTD以降ユーザー数 | B18: =SUM(D18:G18) -> 42 | C18: =AVERAGE(D18:G18) -> 10.5 | D18: =D10+D12+D14+D16 -> 22 | E18: =E10+E12+E14+E16 -> 6 | F18: =F10+F12+F14+F16 -> 5 | G18: =G10+G12+G14+G16 -> 9
A19: 今月登録FTD以降ユーザー割合 | B19: =SUM(D19:G19) -> 0.56609718 | C19: =AVERAGE(D19:G19) -> 0.1415243 | D19: =D18/D4 -> 0.13664596 | E19: =E18/E4 -> 0.12 | F19: =F18/F4 -> 0.12195122 | G19: =G18/G4 -> 0.1875
A20: 総入金回数 | B20: =SUM(D20:G20) -> 44 | C20: =AVERAGE(D20:G20) -> 11 | D20: 5 | E20: 13 | F20: 9 | G20: 17
A21: 入金者数(ユニーク) | B21: =SUM(D21:G21) -> 32 | C21: =AVERAGE(D21:G21) -> 8 | D21: 4 | E21: 9 | F21: 7 | G21: 12
A22: アクティブプレイ人数 | B22: 84 | C22: =AVERAGE(D22:G22) -> 10 | D22: 6 | E22: 9 | F22: 11 | G22: 14
A23: 総入金額 / Total DP amt | B23: =SUM(D23:G23) -> 586146 | C23: =AVERAGE(D23:G23) -> 146536.5 | D23: 96446 | E23: 224500 | F23: 90000 | G23: 175200
A24: 平均入金額(一回の入金額) / Ave amt per DP | B24: =SUM(D24:G24) -> 56864.313 | C24: =AVERAGE(D24:G24) -> 14216.078 | D24: =D23/D20 -> 19289.2 | E24: =E23/E20 -> 17269.231 | F24: =F23/F20 -> 10000 | G24: =G23/G20 -> 10305.882
A25: 平均入金額(ユニークユーザー) / Ave DP amt (Unique user) | B25: =SUM(D25:G25) -> 76513.087 | C25: =AVERAGE(D25:G25) -> 19128.272 | D25: =D23/D21 -> 24111.5 | E25: =E23/E21 -> 24944.444 | F25: =F23/F21 -> 12857.143 | G25: =G23/G21 -> 14600
A26: 総出金回数 | D26: 0 | E26: 0 | F26: 7 | G26: 7
A27: 総出金人数 | D27: 0 | E27: 0 | F27: 5 | G27: 6
A28: 総出金額 / Total WD amt | B28: =SUM(D28:G28) -> 528463 | C28: =AVERAGE(D28:G28) -> 132115.75 | D28: 0 | E28: 0 | F28: 240587 | G28: 287876
A29: 入金額に対して出金割合
A30: T/O(リアルのみ) / Total real bet | B30: =SUM(D30:G30) -> 5043994.2 | C30: =AVERAGE(D30:G30) -> 1260998.6 | D30: 449205 | E30: 1168610 | F30: 1223669.2 | G30: 2202510
A31: T/O率(リアルのみ) / Total real bet ratio | B31: =B30/B23 -> 8.6053546 | C31: =AVERAGE(D31:G31) -> 9.0076747 | D31: =D30/D23 -> 4.6575804 | E31: =E30/E23 -> 5.2053898 | F31: =F30/F23 -> 13.596324 | G31: =G30/G23 -> 12.571404
A32: T/O(ボーナス+リアルマネーの合計) / Total bet (Real+Bonus) | B32: =SUM(D32:G32) -> 5043994.2 | C32: =AVERAGE(D32:G32) -> 1260998.6 | D32: =D30 -> 449205 | E32: =E30 -> 1168610 | F32: =F30 -> 1223669.2 | G32: =G30 -> 2202510
A33: 勝利金(リアルのみ) / Winning amt (Real) | B33: =SUM(D33:G33) -> 4980421.4 | C33: =AVERAGE(D33:G33) -> 1245105.4 | D33: 374255.4 | E33: 1088771 | F33: 1273949 | G33: 2243446
A34: 勝利金(ボーナスのみ) / Winning amt (Bonus) | B34: =SUM(D34:G34) -> 0 | C34: =AVERAGE(D34:G34) -> 0 | D34: 0 | E34: 0 | F34: ¥0 | G34: 0
A35: 勝利金(ボーナス+リアルマネーの合計) / Winning (Bonus+Real) | B35: =SUM(D35:G35) -> 4980421.4 | C35: =AVERAGE(D35:G35) -> 1245105.4 | D35: =D33 -> 374255.4 | E35: =E33 -> 1088771 | F35: =F33 -> 1273949 | G35: =G33 -> 2243446
A36: リアルマネー残高 / Real Money Balance | B36: =SUM(D36:G36) -> 12692491 | C36: =AVERAGE(D36:G36) -> 3173122.8 | D36: 0 | E36: 4311521 | F36: 4243937 | G36: 4137033
A37: ボーナス・マネー残高 / Bonus Money Balance | B37: =SUM(D37:G37) -> 2199720 | C37: =AVERAGE(D37:G37) -> 549930 | D37: 0 | E37: 0 | F37: 1099879 | G37: 1099841
A38: RTP | B38: =SUM(D38:G38) -> 3.8245064 | C38: =AVERAGE(D38:G38) -> 0.95612659 | D38: =D35/D32 -> 0.83315057 | E38: =E35/E32 -> 0.93168037 | F38: =F35/F32 -> 1.0410894 | G38: =G35/G32 -> 1.0185861
A39: T/O(ボーナスのみ) / Total bet (Bonus) | B39: =SUM(D39:G39) -> 0 | C39: =AVERAGE(D39:G39) -> 0 | D39: 0 | E39: 0 | F39: ¥0 | G39: ¥1
A40: T/O率(ボーナスのみ) / Total bet ratio (Bonus) | B40: =SUM(D40:G40) -> 0 | C40: =AVERAGE(D40:G40) -> 0 | D40: 0 | E40: 0 | F40: 0.00% | G40: 0.00%
...

Sheet 202512
A1: 項目名 | B1: 月次合計 | C1: 日次平均 | D1: 12/1 | E1: 12/2 | F1: 12/3 | G1: 12/4 | H1: 12/5 | I1: 12/6 | J1: 12/7 | K1: 12/8 | L1: 12/9 | M1: 12/10 | N1: 12/11 | O1: 12/12 | P1: 12/13 | Q1: 12/14 | R1: 12/15 | S1: 12/16 | T1: 12/17 | U1: 12/18 | V1: 12/19 | W1: 12/20 | X1: 12/21 | Y1: 12/22 | Z1: 12/23 | AA1: 12/24 | AB1: 12/25 | AC1: 12/26 | AD1: 12/27 | AE1: 12/28 | AF1: 12/29 | AG1: 12/30 | AH1: 12/31
D2: 月 | E2: 火 | F2: 水 | G2: 木 | H2: 金 | I2: 土 | J2: 日 | K2: 月 | L2: 火 | M2: 水 | N2: 木 | O2: 金 | P2: 土 | Q2: 日 | R2: 月 | S2: 火 | T2: 水 | U2: 木 | V2: 金 | W2: 土 | X2: 日 | Y2: 月 | Z2: 火 | AA2: 水 | AB2: 木 | AC2: 金 | AD2: 土 | AE2: 日 | AF2: 月 | AG2: 火 | AH2: 水
A3: 全体KPI
A4: 登録人数 | B4: =SUM(D4:AH4) -> 2552 | C4: =AVERAGE(D4:AH4) -> 82.322581 | D4: 33 | E4: 37 | F4: 29 | G4: 56 | H4: =44-7 -> 37 | I4: =36-1 -> 35 | J4: =39-1 -> 38 | K4: =32-1 -> 31 | L4: =40-5 -> 35 | M4: =69-26 -> 43 | N4: =34-2 -> 32 | O4: =41-3 -> 38 | P4: 46 | Q4: 59 | R4: 72 | S4: =84-1 -> 83 | T4: =62-1 -> 61 | U4: 29 | V4: =31-1 -> 30 | W4: 36 | X4: 43 | Y4: 116 | Z4: 208 | AA4: 175 | AB4: 211 | AC4: 156 | AD4: 140 | AE4: 133 | AF4: 69 | AG4: 164 | AH4: 277
A5: ログインユーザー数 | B5: =SUM(D5:AH5) -> 2399 | C5: =AVERAGE(D5:AH5) -> 79.966667 | D5: 25 | E5: 9 | F5: 32 | G5: 36 | H5: 44 | I5: 34 | J5: 31 | K5: 31 | L5: 36 | M5: 38 | N5: 39 | O5: 40 | P5: 47 | R5: 46 | S5: 57 | T5: 67 | U5: 51 | V5: 61 | W5: 67 | X5: 48 | Y5: 54 | Z5: 81 | AA5: 118 | AB5: 115 | AC5: 148 | AD5: 147 | AE5: 202 | AF5: 219 | AG5: 188 | AH5: 288
A6: SMS認証 | B6: =SUM(D6:AH6) -> 2521 | C6: =AVERAGE(D6:AH6) -> 81.322581 | D6: 25 | E6: 21 | F6: 24 | G6: 54 | H6: 37 | I6: 35 | J6: 38 | K6: 31 | L6: 35 | M6: 43 | N6: 32 | O6: 38 | P6: 46 | Q6: 59 | R6: 72 | S6: 83 | T6: 61 | U6: 29 | V6: 30 | W6: 36 | X6: 43 | Y6: 116 | Z6: 208 | AA6: 175 | AB6: 211 | AC6: 156 | AD6: 140 | AE6: 133 | AF6: 69 | AG6: 164 | AH6: 277
A7: 登録に対してSMS認証割合 | B7: =C7 -> 0.97151662 | C7: =AVERAGE(D7:AH7) -> 0.97151662 | D7: =D6/D4 -> 0.75757576 | E7: =E6/E4 -> 0.56756757 | F7: =F6/F4 -> 0.82758621 | G7: =G6/G4 -> 0.96428571 | H7: =H6/H4 -> 1 | I7: =I6/I4 -> 1 | J7: =J6/J4 -> 1 | K7: =K6/K4 -> 1 | ... AH7: =AH6/AH4 -> 1
A8: 入金不要ボーナス使用済ユーザー数 | B8: =SUM(D8:AH8) -> 1554 | C8: =AVERAGE(Y8:AH8) -> 155.4 | D8: 0 | E8: 0 | F8: 0 | G8: 0 | H8: 0 | I8: 0 | J8: 0 | K8: 0 | L8: 0 | M8: 0 | N8: 0 | O8: 0 | P8: 0 | Q8: 0 | R8: 0 | S8: 0 | T8: 0 | U8: 0 | V8: 0 | W8: 0 | X8: 0 | Y8: 106 | Z8: 184 | AA8: 166 | AB8: 210 | AC8: 136 | AD8: 123 | AE8: 133 | AF8: 60 | AG8: 162 | AH8: 274
A9: 登録に対してNDB使用割合 | B9: =SUM(D9:AH9) -> 9.3391467 | C9: =AVERAGE(Y9:AH9) -> 0.93391467 | D9: =D8/D4 -> 0 | E9: =E8/E4 -> 0 | F9: 0 | G9: 0 | H9: 0 | I9: 0 | J9: 0 | K9: 0 | L9: 0 | M9: 0 | N9: 0 | O9: 0 | P9: 0 | Q9: 0 | R9: 0 | S9: 0 | T9: 0 | U9: 0 | V9: 0 | W9: 0 | X9: 0 | Y9: =Y8/Y4 -> 0.9137931 | Z9: =Z8/Z4 -> 0.88461538 | AA9: =AA8/AA4 -> 0.94857143 | AB9: =AB8/AB4 -> 0.99526066 | AC9: =AC8/AC4 -> 0.87179487 | AD9: =AD8/AD4 -> 0.87857143 | AE9: =AE8/AE4 -> 1 | AF9: =AF8/AF4 -> 0.86956522 | ... AH9: =AH8/AH4 -> 0.98916968
A10: FTDのみ入金者数 | B10: =SUM(D10:AH10) -> 231 | C10: =AVERAGE(D10:AH10) -> 7.4516129 | D10: 3 | E10: 3 | F10: 1 | G10: 3 | H10: 4 | I10: 1 | J10: 2 | K10: 1 | L10: 4 | M10: 4 | N10: 2 | O10: 4 | P10: 1 | Q10: 8 | R10: 9 | S10: 9 | T10: 5 | U10: 3 | V10: 1 | W10: 5 | X10: 8 | Y10: 6 | Z10: 13 | AA10: 9 | AB10: 8 | AC10: 16 | AD10: 15 | AE10: 6 | AF10: 5 | AG10: 12 | AH10: 60
A11: 登録に対してFTDのみの割合 | B11: =C11 -> 0.084250455 | C11: =AVERAGE(D11:AH11) -> 0.084250455 | D11: =D10/D4 -> 0.090909091 | E11: =E10/E4 -> 0.081081081 | F11: =F10/F4 -> 0.034482759 | G11: =G10/G4 -> 0.053571429 | H11: =H10/H4 -> 0.10810811 | I11: =I10/I4 -> 0.028571429 | J11: =J10/J4 -> 0.052631579 | K11: =K10/K4 -> 0.032258065 | ... AH11: =AH10/AH4 -> 0.2166065
A12: 2nd入金のみユーザー数 | B12: =SUM(D12:AH12) -> 66 | C12: =AVERAGE(D12:AH12) -> 2.1290323 | D12: 1 | E12: 3 | F12: 0 | G12: 2 | H12: 0 | I12: 0 | J12: 2 | K12: 0 | L12: 0 | M12: 2 | N12: 1 | O12: 2 | P12: 1 | Q12: 1 | R12: 2 | S12: 4 | T12: 2 | U12: 1 | V12: 2 | W12: 2 | X12: 1 | Y12: 2 | Z12: 4 | AA12: 3 | AB12: 4 | AC12: 3 | AD12: 8 | AE12: 2 | AF12: 2 | AG12: 3 | AH12: 6
A13: 登録に対して2nd使用割合 | B13: =C13 -> 0.028724262 | C13: =AVERAGE(D13:AH13) -> 0.028724262 | D13: =D12/D4 -> 0.03030303 | E13: =E12/E4 -> 0.081081081 | F13: =F12/F4 -> 0 | G13: =G12/G4 -> 0.035714286 | H13: =H12/H4 -> 0 | I13: =I12/I4 -> 0 | J13: =J12/J4 -> 0.052631579 | K13: =K12/K4 -> 0 | ... AH13: =AH12/AH4 -> 0.02166065
A14: 3nd入金のみユーザー数 | B14: =SUM(D14:AH14) -> 30 | C14: =AVERAGE(D14:AH14) -> 0.96774194 | D14: 0 | E14: 1 | F14: 1 | G14: 0 | H14: 0 | I14: 0 | J14: 3 | K14: 1 | L14: 0 | M14: 2 | N14: 1 | O14: 2 | P14: 0 | Q14: 0 | R14: 2 | S14: 1 | T14: 2 | U14: 1 | V14: 1 | W14: 0 | X14: 0 | Y14: 1 | Z14: 2 | AA14: 1 | AB14: 2 | AC14: 1 | AD14: 1 | AE14: 0 | AF14: 2 | AG14: 2 | AH14: 0
A15: 登録に対して3nd使用割合 | B15: =C15 -> 0.017151618 | C15: =AVERAGE(D15:AH15) -> 0.017151618 | D15: =D14/D4 -> 0 | E15: =E14/E4 -> 0.027027027 | F15: =F14/F4 -> 0.034482759 | G15: =G14/G4 -> 0 | H15: =H14/H4 -> 0 | I15: =I14/I4 -> 0 | J15: =J14/J4 -> 0.078947368 | K15: =K14/K4 -> 0.032258065 | ... AH15: =AH14/AH4 -> 0
A16: 4nd入金以降ユーザー数 | B16: =SUM(D16:AH16) -> 45 | C16: =AVERAGE(D16:AH16) -> 1.4516129 | D16: 4 | E16: 2 | F16: 3 | G16: 5 | H16: 2 | I16: 4 | J16: 0 | K16: 4 | L16: 2 | M16: 1 | N16: 1 | O16: 1 | P16: 0 | Q16: 1 | R16: 1 | S16: 1 | T16: 0 | U16: 3 | V16: 3 | W16: 0 | X16: 0 | Y16: 0 | Z16: 1 | AA16: 1 | AB16: 0 | AC16: 1 | AD16: 2 | AE16: 0 | AF16: 0 | AG16: 1 | AH16: 1
A17: 登録に対して4nd使用割合 | B17: =C17 -> 0.035180541 | C17: =AVERAGE(D17:AH17) -> 0.035180541 | D17: =D16/D4 -> 0.12121212 | E17: =E16/E4 -> 0.054054054 | F17: =F16/F4 -> 0.10344828 | G17: =G16/G4 -> 0.089285714 | H17: =H16/H4 -> 0.054054054 | I17: =I16/I4 -> 0.11428571 | J17: =J16/J4 -> 0 | K17: =K16/K4 -> 0.12903226 | ... AH17: =AH16/AH4 -> 0.0036101083
A18: 今月登録のFTD以降ユーザー数 | B18: =347+106+57+203 -> 713 | C18: =AVERAGE(D18:AH18) -> 12 | D18: =D10+D12+D14+D16 -> 8 | E18: =E10+E12+E14+E16 -> 9 | F18: =F10+F12+F14+F16 -> 5 | G18: =G10+G12+G14+G16 -> 10 | H18: =H10+H12+H14+H16 -> 6 | I18: =I10+I12+I14+I16 -> 5 | J18: =J10+J12+J14+J16 -> 7 | K18: =K10+K12+K14+K16 -> 6 | ... AH18: =AH10+AH12+AH14+AH16 -> 67
A19: 今月登録FTD以降ユーザー割合 | B19: =C19 -> 0.16530688 | C19: =AVERAGE(D19:AH19) -> 0.16530688 | D19: =D11+D13+D15+D17 -> 0.24242424 | E19: =E11+E13+E15+E17 -> 0.24324324 | F19: =F11+F13+F15+F17 -> 0.17241379 | G19: =G11+G13+G15+G17 -> 0.17857143 | H19: =H11+H13+H15+H17 -> 0.16216216 | I19: =I11+I13+I15+I17 -> 0.14285714 | J19: =J11+J13+J15+J17 -> 0.18421053 | K19: =K11+K13+K15+K17 -> 0.19354839 | ... AH19: =AH11+AH13+AH15+AH17 -> 0.24187726
A20: 今月登録のアクティブユーザー数 | B20: 768
A21: 前月登録のアクティブユーザー数 | B21: 76
A22: 前々月登録のアクティブユーザー数 | B22: -
A23: 3か月以上アクティブプレイヤー数 | B23: -
A24: 総入金回数 | B24: =SUM(D24:AH24) -> 3948 | C24: =AVERAGE(D24:AH24) -> 127.35484 | D24: 42 | E24: 27 | F24: 51 | G24: 38 | H24: 54 | I24: 40 | J24: 49 | K24: 71 | L24: 59 | M24: 107 | N24: 103 | O24: 71 | P24: 88 | Q24: 64 | R24: 116 | S24: 126 | T24: 148 | U24: 108 | V24: 155 | W24: 120 | X24: 119 | Y24: 123 | Z24: 184 | AA24: 170 | AB24: 231 | AC24: 247 | AD24: 194 | AE24: 190 | AF24: 231 | AG24: 267 | AH24: 355
A25: 入金者数(デイリーユニーク) | B25: =SUM(D25:AH25) -> 2234 | C25: =AVERAGE(D25:AH25) -> 72.064516 | D25: 22 | E25: 18 | F25: 21 | G25: 15 | H25: 38 | I25: 22 | J25: 29 | K25: 35 | L25: 29 | M25: 55 | N25: 44 | O25: 37 | P25: 43 | Q25: 38 | R25: 60 | S25: 74 | T25: 70 | U25: 59 | V25: 75 | W25: 66 | X25: 69 | Y25: 71 | Z25: 100 | AA25: 95 | AB25: 121 | AC25: 145 | AD25: 109 | AE25: 127 | AF25: 139 | AG25: 156 | AH25: 252
A26: アクティブプレイ人数（ユニーク） | B26: 798 | C26: =AVERAGE(D26:AH26) -> 142.41935 | D26: 23 | E26: 28 | F26: 27 | G26: 19 | H26: 44 | I26: 30 | J26: 34 | K26: 41 | L26: 38 | M26: 67 | N26: 53 | O26: 47 | P26: 52 | Q26: 50 | R26: 70 | S26: 88 | T26: 86 | U26: 82 | V26: 97 | W26: 93 | X26: 88 | Y26: 176 | Z26: 308 | AA26: 319 | AB26: 340 | AC26: 337 | AD26: 299 | AE26: 331 | AF26: 300 | AG26: 366 | AH26: 482
A27: 総入金額 / Total DP amt | B27: =B193 -> 66633871 | C27: =AVERAGE(D27:AH27) -> 3056096.6 | D27: 945497 | E27: 349000 | F27: 438901 | G27: 792010 | H27: 1645913 | I27: 815512 | J27: 1218881 | K27: 1997198 | L27: 1538477 | M27: 2979139 | N27: 2730300 | O27: 2009507 | P27: 2275078 | Q27: 2904624 | R27: 2293456 | S27: 3684438 | T27: 4433098 | U27: 2314931 | V27: 3564619 | W27: 2441598 | X27: 2884129 | Y27: 3942853 | Z27: 3778360 | AA27: 4704279 | AB27: 5142895 | AC27: 5790196 | AD27: 5145990 | AE27: 3577109 | AF27: 7101798 | AG27: 6150880 | AH27: 5148329
A28: 平均入金額(一回の入金額) / Ave amt per DP | B28: =SUM(D28:AH28) -> 756310.37 | C28: =AVERAGE(D28:AH28) -> 24397.109 | D28: =D27/D24 -> 22511.833 | E28: =E27/E24 -> 12925.926 | F28: =F27/F24 -> 8605.902 | G28: =G27/G24 -> 20842.368 | H28: =H27/H24 -> 30479.87 | I28: =I27/I24 -> 20387.8 | J28: =J27/J24 -> 24875.122 | K28: =K27/K24 -> 28129.549 | ... AH28: =AH27/AH24 -> 14502.335
A29: 平均入金額(ユニークユーザー) / Ave DP amt (Unique user) | B29: =SUM(D29:AH29) -> 1396968.9 | C29: =AVERAGE(D29:AH29) -> 45063.512 | D29: =D27/D25 -> 42977.136 | E29: =E27/E25 -> 19388.889 | F29: =F27/F25 -> 20900.048 | G29: =G27/G25 -> 52800.667 | H29: =H27/H25 -> 43313.5 | I29: =I27/I25 -> 37068.727 | J29: =J27/J25 -> 42030.379 | K29: =K27/K25 -> 57062.8 | ... AH29: =AH27/AH25 -> 20429.877
A30: 総出金回数 | B30: =SUM(D30:AH30) -> 878 | C30: =AVERAGE(D30:AH30) -> 28.322581 | D30: 2 | E30: 9 | F30: 13 | G30: 11 | H30: 9 | I30: 12 | J30: 12 | K30: 11 | L30: 11 | M30: 27 | N30: 10 | O30: 14 | P30: 10 | Q30: 13 | R30: 21 | S30: 25 | T30: 34 | U30: 20 | V30: 30 | W30: 26 | X30: 27 | Y30: 30 | Z30: 43 | AA30: 32 | AB30: 47 | AC30: 82 | AD30: 53 | AE30: 41 | AF30: 57 | AG30: 78 | AH30: 68
A31: 総出金人数 | B31: =SUM(D31:AH31) -> 624 | C31: =AVERAGE(D31:AH31) -> 20.129032 | D31: 2 | E31: 7 | F31: 9 | G31: 7 | H31: 7 | I31: 6 | J31: 8 | K31: 9 | L31: 10 | M31: 13 | N31: 6 | O31: 9 | P31: 7 | Q31: 9 | R31: 15 | S31: 21 | T31: 21 | U31: 17 | V31: 22 | W31: 18 | X31: 20 | Y31: 23 | Z31: 28 | AA31: 25 | AB31: 34 | AC31: 48 | AD31: 38 | AE31: 34 | AF31: 45 | AG31: 53 | AH31: 53
A32: 総出金額 / Total WD amt | B32: =B201 -> 48341793 | C32: =AVERAGE(D32:AH32) -> 1927316.2 | D32: 65000 | E32: 296440 | F32: 1582558 | G32: 587100 | H32: 749292 | I32: 1402604 | J32: 700720 | K32: 552268 | L32: 565000 | M32: 2047916 | N32: 366553 | O32: 2829504 | P32: 1341051 | Q32: 1298576 | R32: 1407954 | S32: 1571617 | T32: 3663422 | U32: 1496310 | V32: 1832892 | W32: 1646195 | X32: 1484922 | Y32: 1991337 | Z32: 3380070 | AA32: 2385924 | AB32: 2618849 | AC32: 5654825 | AD32: 4176571 | AE32: 1342656 | AF32: 3297388 | AG32: 3393454 | AH32: 4017833
A33: 入金額に対して出金割合 | B33: =B32/B27 -> 0.72548379 | C33: =AVERAGE(D33:AH33) -> 0.90739079 | D33: =D32/D27 -> 0.068746913 | E33: =E32/E27 -> 0.84939828 | F33: =F32/F27 -> 3.6057289 | G33: =G32/G27 -> 0.74127852 | H33: =H32/H27 -> 0.45524399 | I33: =I32/I27 -> 1.719906 | J33: =J32/J27 -> 0.57488795 | K33: =K32/K27 -> 0.27652141 | ... O33: =O32/O27 -> 1.4080588
A34: T/O(リアルのみ) / Total real bet | B34: =SUM(D34:AH34) -> 1120432234 | C34: =AVERAGE(D34:AH34) -> 36142975 | D34: 5578051.2 | E34: 8403858.4 | F34: 23485815 | G34: 5800641 | H34: 13513206 | I34: 24148455 | J34: 16245815 | K34: 19277349 | L34: 16551076 | M34: 19662416 | N34: 20406699 | O34: 18747084 | P34: 13816335 | Q34: 28136316 | R34: 30020431 | S34: 32487601 | T34: 37302702 | U34: 45408503 | V34: 24870691 | W34: 22885651 | X34: 19865158 | Y34: 17786382 | Z34: 39858513 | AA34: 62480982 | AB34: 56547424 | AC34: 74079231 | AD34: 133999844 | AE34: 75565191 | AF34: 106387768 | AG34: 59752300 | AH34: 47360745
A35: T/O率(リアルのみ) / Total real bet ratio | B35: =B34/B27 -> 16.814755 | C35: =AVERAGE(D35:AH35) -> 13.158128 | D35: =D34/D27 -> 5.8995969 | E35: =E34/E27 -> 24.079824 | F35: =F34/F27 -> 53.510507 | G35: =G34/G27 -> 7.3239492 | H35: =H34/H27 -> 8.2101581 | I35: =I34/I27 -> 29.611403 | J35: =J34/J27 -> 13.328467 | K35: =K34/K27 -> 9.6521972 | ... AH35: =AH34/AH27 -> 9.199246
A36: T/O(ボーナス+リアルマネーの合計) / Total bet (Real+Bonus) | B36: =SUM(D36:AH36) -> 1120432234 | C36: =AVERAGE(D36:AH36) -> 36142975 | D36: =D34+D43 -> 5578051.2 | E36: =E34+E43 -> 8403858.4 | F36: =F34+F43 -> 23485815 | G36: =G34+G43 -> 5800641 | H36: =H34+H43 -> 13513206 | I36: =I34+I43 -> 24148455 | J36: =J34+J43 -> 16245815 | K36: =K34+K43 -> 19277349 | ... AH36: =AH34+AH43 -> 47360745
A37: 勝利金(リアルのみ) / Winning amt (Real) | B37: =SUM(D37:AH37) -> 1084887870 | C37: =AVERAGE(D37:AH37) -> 34996383 | D37: 5481706.2 | E37: 8095355.2 | F37: 24638687 | G37: 5380834 | H37: 13195295 | I37: 25771772 | J37: 14032319 | K37: 18207736 | L37: 15465830 | M37: 18572438 | N37: 18794351 | O37: 18224289 | P37: 14533094 | Q37: 25981992 | R37: 28429302 | S37: 30830700 | T37: 36220914 | U37: 43531998 | V37: 23520845 | W37: 21347954 | X37: 18800550 | Y37: 17348497 | Z37: 38934810 | AA37: 61209012 | AB37: 58333300 | AC37: 74770471 | AD37: 129994814 | AE37: 73671644 | AF37: 98632911 | AG37: 56271890 | AH37: 46662560
A38: 勝利金(ボーナスのみ) / Winning amt (Bonus) | B38: =SUM(D38:AH38) -> 387.8 | C38: =AVERAGE(D38:AH38) -> 12.509677 | D38: 15710.6 | E38: 341 | F38: -1431 | G38: 0 | H38: 0 | I38: 16800.6 | J38: 16800.6 | K38: 0 | L38: 0 | M38: -15353 | N38: 0 | O38: 0 | P38: 0 | Q38: 0 | R38: 0 | S38: 100 | T38: 85 | U38: -18866 | V38: -18866 | W38: 1692 | X38: 0 | Y38: -40 | Z38: -40 | AA38: 10 | AB38: 0 | AC38: 40 | AD38: 0 | AE38: 0 | AF38: 0 | AG38: 3404 | AH38: 0
A39: 勝利金(ボーナス+リアルマネーの合計) / Winning (Bonus+Real) | B39: =SUM(D39:AH39) -> 1084888258 | C39: =AVERAGE(D39:AH39) -> 34996395 | D39: =D38+D37 -> 5497416.8 | E39: =E38+E37 -> 8095696.2 | F39: =F38+F37 -> 24637256 | G39: =G38+G37 -> 5380834 | H39: =H38+H37 -> 13195295 | I39: =I38+I37 -> 25788572 | J39: =J38+J37 -> 14049120 | K39: =K38+K37 -> 18207736 | ... AH39: =AH38+AH37 -> 46662560
A40: リアルマネー残高 / Real Money Balance | B40: =LOOKUP(9^9, C40:AH40) -> 7288550 | C40: =AVERAGE(D40:AH40) -> 6581734.5 | D40: 4795205 | E40: 5659793 | F40: 4437436 | G40: 4459250 | H40: 4987653 | I40: 6402196 | J40: 4828189 | K40: 5138001 | L40: 4748285 | M40: 5092791 | N40: 5705485 | P40: 6758249 | R40: 6099617 | S40: 6382281 | T40: 6065153 | U40: 5352440 | V40: 5795843 | W40: 4921791 | X40: 5291502 | Y40: 6726519 | Z40: 6594095 | AA40: 7791521 | AB40: 11989746 | AC40: 12933406 | AD40: 9799360 | AE40: 10510352 | AF40: 6988030 | AG40: 7327562 | AH40: 7288550
...

Sheet 202601
A1: 項目名 | B1: 月次合計 | C1: 日次平均 | D1: 46023 | E1: 46024 | F1: 46025 | G1: 46026 | H1: 46027 | I1: 46028 | J1: 46029 | K1: 46030 | L1: 46031 | M1: 46032 | N1: 46033 | O1: 46034 | P1: 46035 | Q1: 46036 | R1: 46037 | S1: 46038 | T1: 46039 | U1: 46040 | V1: 46041 | W1: 46042 | X1: 46043 | Y1: 46044 | Z1: 46045 | AA1: 46046 | AB1: 46047 | AC1: 46048 | AD1: 46049 | AE1: 46050 | AF1: 46051 | AG1: 46052 | AH1: 46053
D2: 木 | E2: 金 | F2: 土 | G2: 日 | H2: 月 | I2: 火 | J2: 水 | K2: 木 | L2: 金 | M2: 土 | N2: 日 | O2: 月 | P2: 火 | Q2: 水 | R2: 木 | S2: 金 | T2: 土 | U2: 日 | V2: 月 | W2: 火 | X2: 水 | Y2: 木 | Z2: 金 | AA2: 土 | AB2: 日 | AC2: 月 | AD2: 火 | AE2: 水 | AF2: 木 | AG2: 金 | AH2: 土
A3: 全体KPI | B3: =SUM(D3:AH3) -> 0
A4: 登録人数 | B4: =SUM(D4:AH4) -> 5685 | C4: =AVERAGE(D4:AH4) -> 203.03571 | D4: 195 | E4: 141 | F4: 206 | G4: 159 | H4: 159 | I4: 278 | J4: 263 | K4: 219 | L4: 69 | M4: 172 | N4: 100 | O4: 382 | P4: 242 | Q4: 125 | R4: 331 | S4: 103 | T4: 114 | U4: 123 | V4: 232 | W4: 185 | X4: 107 | Y4: 314 | Z4: 146 | AA4: 244 | AB4: 209 | AC4: 265 | AD4: 272 | AE4: 330
A5: ログインユーザー数 | B5: 3459 | C5: =AVERAGE(D5:AH5) -> 252.25926 | D5: 186 | E5: 142 | F5: 153 | G5: 146 | I5: 184 | J5: 244 | K5: 220 | L5: 312 | M5: 261 | N5: 274 | O5: 234 | P5: 277 | Q5: 257 | R5: 260 | S5: 294 | T5: 275 | U5: 237 | V5: 205 | W5: 252 | X5: 273 | Y5: 273 | Z5: 303 | AA5: 272 | AB5: 280 | AC5: 287 | AD5: 327 | AE5: 383
A6: SMS認証 | B6: =SUM(D6:AH6) -> 5685 | C6: =AVERAGE(D6:AH6) -> 203.03571 | D6: 195 | E6: 141 | F6: 206 | G6: 159 | H6: 159 | I6: 278 | J6: 263 | K6: 219 | L6: 69 | M6: 172 | N6: 100 | O6: 382 | P6: 242 | Q6: 125 | R6: 331 | S6: 103 | T6: 114 | U6: 123 | V6: 232 | W6: 185 | X6: 107 | Y6: 314 | Z6: 146 | AA6: 244 | AB6: 209 | AC6: 265 | AD6: 272 | AE6: 330
A7: 登録に対してSMS認証割合 | B7: =C7 -> 1 | C7: =AVERAGE(D7:AH7) -> 1 | D7: =D6/D4 -> 1 | E7: =E6/E4 -> 1 | F7: =F6/F4 -> 1 | G7: =G6/G4 -> 1 | H7: =H6/H4 -> 1 | I7: =I6/I4 -> 1 | J7: =J6/J4 -> 1 | K7: =K6/K4 -> 1 | ... AE7: =AE6/AE4 -> 1
A8: 入金不要ボーナス使用済ユーザー数 | B8: 6211 | C8: =AVERAGE(D8:AH8) -> 180.75 | D8: 207 | E8: 134 | F8: 229 | G8: 134 | H8: 164 | I8: 220 | J8: 233 | K8: 162 | L8: 93 | M8: 135 | N8: 185 | O8: 178 | P8: 249 | Q8: 210 | R8: 198 | S8: 170 | T8: 136 | U8: 185 | V8: 184 | W8: 158 | X8: 217 | Y8: 251 | Z8: 194 | AA8: 112
A9: 登録に対してNDB使用割合 | B9: =B8/B4 -> 1.0925242 | C9: =AVERAGE(D9:AH9) -> 0.3079836 | D9: =D8/D4 -> 1.0615385 | E9: =E8/E4 -> 0.95035461 | F9: =F8/F4 -> 1.1116505 | G9: =G8/G4 -> 0.8427673 | H9: =H8/H4 -> 1.0314465 | I9: =I8/I4 -> 0.79136691 | J9: =J8/J4 -> 0.88593156 | K9: =K8/K4 -> 0.73972603 | ... M9: =M8/M4 -> 0.78488372 | N9: 0 | O9: 0 | P9: 0 | Q9: 0 | R9: 0 | S9: 0 | T9: 0 | U9: 0 | V9: 0 | W9: 0 | X9: 0 | Y9: 0 | Z9: 0 | AA9: 0 | AB9: 0 | AC9: 0 | AD9: 0 | AE9: 0 | AF9: 0 | AG9: 0 | AH9: 0
A10: FTDのみ入金者数 | B10: 348 | C10: =AVERAGE(D10:AH10) -> 6.1428571 | D10: 6 | E10: 7 | F10: 10 | G10: 8 | H10: 8 | I10: 9 | J10: 12 | K10: 6 | L10: 3 | M10: 7 | N10: 3 | O10: 2 | P10: 7 | Q10: 6 | R10: 10 | S10: 2 | T10: 3 | U10: 5 | V10: 8 | W10: 3 | X10: 5 | Y10: 6 | Z10: 4 | AA10: 6 | AB10: 6 | AC10: 5 | AD10: 6 | AE10: 9
A11: 登録に対して1st使用割合 | B11: =C11 -> 0.032619627 | C11: =AVERAGE(D11:AH11) -> 0.032619627 | D11: =D10/D4 -> 0.030769231 | E11: =E10/E4 -> 0.04964539 | F11: =F10/F4 -> 0.048543689 | G11: =G10/G4 -> 0.050314465 | H11: =H10/H4 -> 0.050314465 | I11: =I10/I4 -> 0.032374101 | J11: =J10/J4 -> 0.045627376 | K11: =K10/K4 -> 0.02739726 | ... AE11: =AE10/AE4 -> 0.027272727
A12: 2ndのみ入金者数 | B12: 45 | C12: =AVERAGE(D12:AH12) -> 1.2857143 | D12: 3 | E12: 1 | F12: 0 | G12: 0 | H12: 1 | I12: 2 | J12: 4 | K12: 0 | L12: 1 | M12: 4 | N12: 0 | O12: 2 | P12: 3 | Q12: 1 | R12: 3 | S12: 0 | T12: 1 | U12: 3 | V12: 0 | W12: 1 | X12: 1 | Y12: 1 | Z12: 0 | AA12: 1 | AB12: 0 | AC12: 0 | AD12: 1 | AE12: 2
A13: 登録に対して2nd使用割合 | B13: =C13 -> 0.006733833 | C13: =AVERAGE(D13:AH13) -> 0.006733833 | D13: =D12/D4 -> 0.015384615 | E13: =E12/E4 -> 0.0070921986 | F13: =F12/F4 -> 0 | G13: =G12/G4 -> 0 | H13: =H12/H4 -> 0.0062893082 | I13: =I12/I4 -> 0.0071942446 | J13: =J12/J4 -> 0.015209125 | K13: =K12/K4 -> 0 | ... AE13: =AE12/AE4 -> 0.0060606061
A14: 3nd入金以降ユーザー数 | B14: 44 | C14: =AVERAGE(D14:AH14) -> 0.85714286 | D14: 1 | E14: 1 | F14: 0 | G14: 4 | H14: 1 | I14: 0 | J14: 1 | K14: 0 | L14: 1 | M14: 1 | N14: 0 | O14: 2 | P14: 2 | Q14: 0 | R14: 3 | S14: 0 | T14: 1 | U14: 0 | V14: 1 | W14: 3 | X14: 0 | Y14: 0 | Z14: 0 | AA14: 1 | AB14: 1 | AC14: 0 | AD14: 0 | AE14: 0
A15: 登録に対して3nd使用割合 | B15: =C15 -> 0.0045900351 | C15: =AVERAGE(D15:AH15) -> 0.0045900351 | D15: =D14/D4 -> 0.0051282051 | E15: =E14/E4 -> 0.0070921986 | F15: =F14/F4 -> 0 | G15: =G14/G4 -> 0.025157233 | H15: =H14/H4 -> 0.0062893082 | I15: =I14/I4 -> 0 | J15: =J14/J4 -> 0.0038022814 | K15: =K14/K4 -> 0 | ... AE15: =AE14/AE4 -> 0
A16: 4nd入金以降ユーザー数 | B16: 162 | C16: =AVERAGE(D16:AH16) -> 1.1428571 | D16: 1 | E16: 2 | F16: 3 | G16: 0 | H16: 4 | I16: 1 | J16: 1 | K16: 1 | L16: 1 | M16: 3 | N16: 1 | O16: 1 | P16: 0 | Q16: 0 | R16: 2 | S16: 1 | T16: 0 | U16: 2 | V16: 1 | W16: 1 | X16: 0 | Y16: 0 | Z16: 0 | AA16: 0 | AB16: 2 | AC16: 2 | AD16: 0 | AE16: 2
A17: 登録に対して4nd使用割合 | B17: =C17 -> 0.006444824 | C17: =AVERAGE(D17:AH17) -> 0.006444824 | D17: =D16/D4 -> 0.0051282051 | E17: =E16/E4 -> 0.014184397 | F17: =F16/F4 -> 0.014563107 | G17: =G16/G4 -> 0 | H17: =H16/H4 -> 0.025157233 | I17: =I16/I4 -> 0.0035971223 | J17: =J16/J4 -> 0.0038022814 | K17: =K16/K4 -> 0.00456621 | ... AE17: =AE16/AE4 -> 0.0060606061
A18: 今月登録のFTD以降ユーザー数 | B18: =B10+B12+B14+B16 -> 599 | C18: =AVERAGE(D18:AH18) -> 8.516129 | D18: =D10+D12+D14+D16 -> 11 | E18: =E10+E12+E14+E16 -> 11 | F18: =F10+F12+F14+F16 -> 13 | G18: =G10+G12+G14+G16 -> 12 | H18: =H10+H12+H14+H16 -> 14 | I18: =I10+I12+I14+I16 -> 12 | J18: =J10+J12+J14+J16 -> 18 | K18: =K10+K12+K14+K16 -> 7 | ... AH18: =AH10+AH12+AH14+AH16 -> 0
A19: 今月登録FTD以降ユーザー割合 | B19: =B18/B4 -> 0.105365 | C19: =AVERAGE(D19:AH19) -> 0.050388319 | D19: =D11+D13+D15+D17 -> 0.056410256 | E19: =E11+E13+E15+E17 -> 0.078014184 | F19: =F11+F13+F15+F17 -> 0.063106796 | G19: =G11+G13+G15+G17 -> 0.075471698 | H19: =H11+H13+H15+H17 -> 0.088050314 | I19: =I11+I13+I15+I17 -> 0.043165468 | J19: =J11+J13+J15+J17 -> 0.068441065 | K19: =K11+K13+K15+K17 -> 0.03196347 | ... AE19: =AE11+AE13+AE15+AE17 -> 0.039393939
A20: 今月登録のアクティブユーザー数 | B20: 598
A21: 前月登録のアクティブユーザー数 | B21: 667
A22: 前々月登録のアクティブユーザー数 | B22: 74
A23: 3か月以上アクティブプレイヤー数 | B23: -
A24: 総入金回数 | B24: =SUM(D24:AH24) -> 8484 | C24: =AVERAGE(D24:AH24) -> 303 | D24: 268 | E24: 232 | F24: 214 | G24: 213 | H24: 308 | I24: 297 | J24: 260 | K24: 248 | L24: 273 | M24: 314 | N24: 267 | O24: 239 | P24: 352 | Q24: 303 | R24: 377 | S24: 312 | T24: 304 | U24: 270 | V24: 260 | W24: 377 | X24: 353 | Y24: 317 | Z24: 379 | AA24: 356 | AB24: 301 | AC24: 336 | AD24: 385 | AE24: 369
A25: 入金者数(デイリーユニーク) | B25: =G193 -> 1542 | C25: =AVERAGE(D25:AH25) -> 161.71429 | D25: 163 | E25: 127 | F25: 123 | G25: 118 | H25: 169 | I25: 153 | J25: 145 | K25: 130 | L25: 158 | M25: 163 | N25: 144 | O25: 145 | P25: 192 | Q25: 165 | R25: 194 | S25: 154 | T25: 164 | U25: 144 | V25: 146 | W25: 188 | X25: 169 | Y25: 174 | Z25: 190 | AA25: 182 | AB25: 168 | AC25: 172 | AD25: 192 | AE25: 196
A26: アクティブプレイ人数（ユニーク） | B26: =B20+B21+B22 -> 1339 | C26: =AVERAGE(D26:AH26) -> 405.32143 | D26: 417 | E26: 329 | F26: 405 | G26: 289 | H26: 354 | I26: 430 | J26: 444 | K26: 341 | L26: 303 | M26: 328 | N26: 395 | O26: 384 | P26: 481 | Q26: 416 | R26: 440 | S26: 383 | T26: 356 | U26: 384 | V26: 380 | W26: 412 | X26: 433 | Y26: 472 | Z26: 444 | AA26: 430 | AB26: 435 | AC26: 436 | AD26: 379 | AE26: 649
A27: 総入金額 / Total DP amt | B27: =B193 -> 129457997 | C27: =AVERAGE(D27:AH27) -> 5450610.5 | D27: 3779495 | E27: 2819739 | F27: 4002694 | G27: 3549751 | H27: 8311890 | I27: 6672779 | J27: 5573653 | K27: 4397152 | L27: 5628868 | M27: 4873108 | N27: 4209074 | O27: 3158505 | P27: 5274526 | Q27: 4534376 | R27: 4808188 | S27: 4999483 | T27: 4904107 | U27: 3990809 | V27: 4775395 | W27: 7969699 | X27: 6639499 | Y27: 5533068 | Z27: 8525244 | AA27: 7725120 | AB27: 5495767 | AC27: 8398889 | AD27: 6958335 | AE27: 5107881
A28: 平均入金額(一回の入金額) / Ave amt per DP | B28: =B27/B24 -> 15259.076 | C28: =AVERAGE(D28:AH28) -> 17862.159 | D28: =D27/D24 -> 14102.593 | E28: =E27/E24 -> 12154.047 | F28: =F27/F24 -> 18704.178 | G28: =G27/G24 -> 16665.498 | H28: =H27/H24 -> 26986.656 | I28: =I27/I24 -> 22467.269 | J28: =J27/J24 -> 21437.127 | K28: =K27/K24 -> 17730.452 | ... AE28: =AE27/AE24 -> 13842.496
A29: 平均入金額(ユニークユーザー) / Ave DP amt (Unique user) | B29: =B27/B25 -> 83954.602 | C29: =AVERAGE(D29:AH29) -> 33456.208 | D29: =D27/D25 -> 23187.086 | E29: =E27/E25 -> 22202.669 | F29: =F27/F25 -> 32542.228 | G29: =G27/G25 -> 30082.636 | H29: =H27/H25 -> 49182.781 | I29: =I27/I25 -> 43612.935 | J29: =J27/J25 -> 38438.986 | K29: =K27/K25 -> 33824.246 | ... AE29: =AE27/AE25 -> 26060.617
A30: 総出金回数 | B30: =SUM(D30:AH30) -> 1866 | C30: =AVERAGE(D30:AH30) -> 66.642857 | D30: 60 | E30: 46 | F30: 46 | G30: 53 | H30: 61 | I30: 65 | J30: 65 | K30: 46 | L30: 72 | M30: 74 | N30: 66 | O30: 50 | P30: 77 | Q30: 64 | R30: 80 | S30: 65 | T30: 85 | U30: 60 | V30: 51 | W30: 71 | X30: 66 | Y30: 69 | Z30: 93 | AA30: 64 | AB30: 74 | AC30: 88 | AD30: 63 | AE30: 92
A31: 総出金人数 | B31: =SUM(D31:AH31) -> 1347 | C31: =AVERAGE(D31:AH31) -> 48.107143 | D31: 48 | E31: 37 | F31: 36 | G31: 39 | H31: 46 | I31: 50 | J31: 42 | K31: 38 | L31: 49 | M31: 45 | N31: 45 | O31: 32 | P31: 59 | Q31: 40 | R31: 54 | S31: 48 | T31: 63 | U31: 41 | V31: 42 | W31: 51 | X31: 51 | Y31: 51 | Z31: 65 | AA31: 53 | AB31: 53 | AC31: 54 | AD31: 51 | AE31: 64
A32: 総出金額 / Total WD amt | B32: =B201 -> 94439992 | C32: =AVERAGE(D32:AH32) -> 3790935.6 | D32: 4902347 | E32: 3140979 | F32: 3280662 | G32: 4139569 | H32: 5061884 | I32: 4386705 | J32: 3086327 | K32: 2622203 | L32: 3623909 | M32: 3932470 | N32: 2615492 | O32: 1666395 | P32: 2209362 | Q32: 2081030 | R32: 3760947 | S32: 4026312 | T32: 3616612 | U32: 4068257 | V32: 2399347 | W32: 5863942 | X32: 3457169 | Y32: 3782050 | Z32: 5897027 | AA32: 4192596 | AB32: 5000943 | AC32: 4417378 | AD32: 4437421 | AE32: 4476863
A33: 入金額に対して出金割合 | B33: =B32/B27 -> 0.72950296 | C33: =AVERAGE(D33:AH33) -> 0.72365114 | D33: =D32/D27 -> 1.2970905 | E33: =E32/E27 -> 1.1139254 | F33: =F32/F27 -> 0.81961349 | G33: =G32/G27 -> 1.1661576 | H33: =H32/H27 -> 0.60899314 | I33: =I32/I27 -> 0.65740301 | J33: =J32/J27 -> 0.55373505 | K33: =K32/K27 -> 0.59634122 | ... AE33: =AE32/AE27 -> 0.87646188
A34: T/O(リアルのみ) / Total real bet | B34: =SUM(D34:AH34) -> 2033078021 | C34: =AVERAGE(D34:AH34) -> 72609929 | D34: 32861849 | E34: 37522938 | F34: 39569424 | G34: 54633736 | H34: 83462989 | I34: 114523955 | J34: 74599086 | K34: 68738303 | L34: 92216045 | M34: 40097378 | N34: 41425426 | O34: 33135945 | P34: 48557101 | Q34: 50690501 | R34: 63006286 | S34: 54588985 | T34: 54588985 | U34: 55796742 | V34: 70455216 | W34: 77376217 | X34: 87361273 | Y34: 65510916 | Z34: 117139905 | AA34: 237392513 | AB34: 115886373 | AC34: 94592577 | AD34: 66624665 | AE34: 60722692
A35: T/O率(リアルのみ) / Total real bet ratio | B35: =B34/B27 -> 15.704538 | C35: =AVERAGE(D35:AH35) -> 13.060946 | D35: =D34/D27 -> 8.6947725 | E35: =E34/E27 -> 13.307238 | F35: =F34/F27 -> 9.885698 | G35: =G34/G27 -> 15.390864 | H35: =H34/H27 -> 10.041397 | I35: =I34/I27 -> 17.162857 | J35: =J34/J27 -> 13.384236 | K35: =K34/K27 -> 15.63246 | ... AE35: =AE34/AE27 -> 11.88804
A36: T/O(ボーナス+リアルマネーの合計) / Total bet (Real+Bonus) | B36: =SUM(D36:AH36) -> 2033078021 | C36: =AVERAGE(D36:AH36) -> 65583162 | D36: =D34+D43 -> 32861849 | E36: =E34+E43 -> 37522938 | F36: =F34+F43 -> 39569424 | G36: =G34+G43 -> 54633736 | H36: =H34+H43 -> 83462989 | I36: =I34+I43 -> 114523955 | J36: =J34+J43 -> 74599086 | K36: =K34+K43 -> 68738303 | ... AH36: =AH34+AH43 -> 0
A37: 勝利金(リアルのみ) / Winning amt (Real) | B37: =SUM(D37:AH37) -> 1963038700 | C37: =AVERAGE(D37:AH37) -> 70108525 | D37: 32544172 | E37: 38310106 | F37: 39654863 | G37: 53106312 | H37: 82129397 | I37: 109076275 | J37: 73676542 | K37: 67787726 | L37: 86142048 | M37: 37471669 | N37: 39668188 | O37: 32943581 | P37: 43904615 | Q37: 47756626 | R37: 62478472 | S37: 54068694 | T37: 54068694 | U37: 54690912 | V37: 71326737 | W37: 73085637 | X37: 82280548 | Y37: 64436580 | Z37: 115529524 | AA37: 229071865 | AB37: 111864253 | AC37: 87927095 | AD37: 60775768 | AE37: 57261801
A38: 勝利金(ボーナスのみ) / Winning amt (Bonus) | B38: =SUM(D38:AH38) -> 1242447 | C38: =AVERAGE(D38:AH38) -> 44373.107 | D38: 0 | E38: 0 | F38: 0 | G38: 0 | H38: 0 | I38: 0 | J38: 0 | K38: 0 | L38: 0 | M38: 0 | N38: 0 | O38: 0 | P38: 0 | Q38: 0 | R38: 0 | S38: 0 | T38: 0 | U38: 0 | V38: 0 | W38: 0 | X38: 0 | Y38: 0 | Z38: -710000 | AA38: 0 | AB38: 2264099 | AC38: -103884 | AD38: -103884 | AE38: -103884
A39: 勝利金(ボーナス+リアルマネーの合計) / Winning (Bonus+Real) | B39: =SUM(D39:AH39) -> 1964281147 | C39: =AVERAGE(D39:AH39) -> 63363908 | D39: =D38+D37 -> 32544172 | E39: =E38+E37 -> 38310106 | F39: =F38+F37 -> 39654863 | G39: =G38+G37 -> 53106312 | H39: =H38+H37 -> 82129397 | I39: =I38+I37 -> 109076275 | J39: =J38+J37 -> 73676542 | K39: =K38+K37 -> 67787726 | ... AH39: =AH38+AH37 -> 0
A40: リアルマネー残高 / Real Money Balance | B40: =LOOKUP(9^9, C40:AH40) -> 11302741 | C40: =AVERAGE(D40:AH40) -> 9910366.3 | D40: 7233571 | E40: 7031022 | F40: 8725910 | G40: 9091789 | I40: 6885686 | J40: 9728845 | K40: 10744435 | L40: 8072992 | M40: 6395376 | N40: 6859009 | O40: 8756590 | P40: 6758249 | Q40: 7380567 | R40: 8790396 | S40: 10061116 | T40: 9349866 | U40: 8016444 | V40: 11201575 | W40: 9703057 | X40: 8909687 | Y40: 9057567 | Z40: 17398408 | AA40: 13109741 | AB40: 18189199 | AC40: 14928730 | AD40: 13897321 | AE40: 11302741
...

Sheet 202602
A1: 項目名 | B1: 月次合計 | C1: 日次平均 | D1: 46054 | E1: 46055 | F1: 46056 | G1: 46057 | H1: 46058 | I1: 46059 | J1: 46060 | K1: 46061 | L1: 46062 | M1: 46063 | N1: 46064 | O1: 46065 | P1: 46066 | Q1: 46067 | R1: 46068 | S1: 46069 | T1: 46070 | U1: 46071 | V1: 46072 | W1: 46073 | X1: 46074 | Y1: 46075 | Z1: 46076 | AA1: 46077 | AB1: 46078 | AC1: 46079 | AD1: 46080 | AE1: 46081
D2: 日 | E2: 月 | F2: 火 | G2: 水 | H2: 木 | I2: 金 | J2: 土 | K2: 日 | L2: 月 | M2: 火 | N2: 水 | O2: 木 | P2: 金 | Q2: 土 | R2: 日 | S2: 月 | T2: 火 | U2: 水 | V2: 木 | W2: 金 | X2: 土 | Y2: 日 | Z2: 月 | AA2: 火 | AB2: 水 | AC2: 木 | AD2: 金 | AE2: 土
A3: 全体KPI | B3: =SUM(D3:AH3) -> 0
A4: 登録人数 | B4: =SUM(D4:AH4) -> 0 | C4: =AVERAGE(D4:AH4) -> #DIV/0!
A5: ログインユーザー数 | C5: =AVERAGE(D5:AH5) -> #DIV/0!
A6: SMS認証 | B6: =SUM(D6:AH6) -> 0 | C6: =AVERAGE(D6:AH6) -> #DIV/0!
A7: 登録に対してSMS認証割合 | B7: =C7 -> #DIV/0! | C7: =AVERAGE(D7:AH7) -> #DIV/0! | D7: =D6/D4 -> #DIV/0!
A8: 入金不要ボーナス使用済ユーザー数 | B8: 4643 | C8: =AVERAGE(D8:AH8) -> #DIV/0!
A9: 登録に対してNDB使用割合 | B9: =SUM(D9:AH9) -> #DIV/0! | C9: =AVERAGE(D9:AH9) -> #DIV/0! | D9: =D8/D4 -> #DIV/0!
A10: FTDのみ入金者数 | B10: 233 | C10: =AVERAGE(D10:AH10) -> #DIV/0!
A11: 登録に対して1st使用割合 | B11: =C11 -> #DIV/0! | C11: =AVERAGE(D11:AH11) -> #DIV/0! | D11: =D10/D4 -> #DIV/0!
A12: 2ndのみ入金者数 | B12: 44 | C12: =AVERAGE(D12:AH12) -> #DIV/0!
A13: 登録に対して2nd使用割合 | B13: =C13 -> #DIV/0! | C13: =AVERAGE(D13:AH13) -> #DIV/0! | D13: =D12/D4 -> #DIV/0!
A14: 3nd入金以降ユーザー数 | B14: 36 | C14: =AVERAGE(D14:AH14) -> #DIV/0!
A15: 登録に対して3nd使用割合 | B15: =C15 -> #DIV/0! | C15: =AVERAGE(D15:AH15) -> #DIV/0! | D15: =D14/D4 -> #DIV/0!
A16: 4nd入金以降ユーザー数 | B16: 116 | C16: =AVERAGE(D16:AH16) -> #DIV/0!
A17: 登録に対して4nd使用割合 | B17: =C17 -> #DIV/0! | C17: =AVERAGE(D17:AH17) -> #DIV/0! | D17: =D16/D4 -> #DIV/0!
A18: 今月登録のFTD以降ユーザー数 | B18: =B10+B12+B14+B16 -> 429 | C18: =AVERAGE(D18:AH18) -> 0 | D18: =D10+D12+D14+D16 -> 0
A19: 今月登録FTD以降ユーザー割合 | B19: =B18/B4 -> #DIV/0! | C19: =AVERAGE(D19:AH19) -> #DIV/0! | D19: =D11+D13+D15+D17 -> #DIV/0!
A20: 今月登録のアクティブユーザー数
A21: 前月登録のアクティブユーザー数
A22: 前々月登録のアクティブユーザー数
A23: 3か月以上アクティブプレイヤー数 | B23: -
A24: 総入金回数 | B24: =SUM(D24:AH24) -> 0 | C24: =AVERAGE(D24:AH24) -> #DIV/0!
A25: 入金者数(デイリーユニーク) | B25: =G193 -> 0 | C25: =AVERAGE(D25:AH25) -> #DIV/0!
A26: アクティブプレイ人数（ユニーク） | B26: =B20+B21+B22 -> 0 | C26: =AVERAGE(D26:AH26) -> #DIV/0!
A27: 総入金額 / Total DP amt | B27: =B193 -> 0 | C27: =AVERAGE(D27:AH27) -> #DIV/0!
A28: 平均入金額(一回の入金額) / Ave amt per DP | B28: =C28 -> #DIV/0! | C28: =AVERAGE(D28:AH28) -> #DIV/0! | D28: =D27/D24 -> #DIV/0!
A29: 平均入金額(ユニークユーザー) / Ave DP amt (Unique user) | B29: =C29 -> #DIV/0! | C29: =AVERAGE(D29:AH29) -> #DIV/0! | D29: =D27/D25 -> #DIV/0!
A30: 総出金回数 | B30: =SUM(D30:AH30) -> 0 | C30: =AVERAGE(D30:AH30) -> #DIV/0!
A31: 総出金人数 | B31: =SUM(D31:AH31) -> 0 | C31: =AVERAGE(D31:AH31) -> #DIV/0!
A32: 総出金額 / Total WD amt | B32: =B201 -> 0 | C32: =AVERAGE(D32:AH32) -> #DIV/0!
A33: 入金額に対して出金割合 | B33: =B32/B27 -> #DIV/0! | C33: =AVERAGE(D33:AH33) -> #DIV/0! | D33: =D32/D27 -> #DIV/0!
A34: T/O(リアルのみ) / Total real bet | B34: =SUM(D34:AH34) -> 0 | C34: =AVERAGE(D34:AH34) -> #DIV/0!
A35: T/O率(リアルのみ) / Total real bet ratio | B35: =B34/B27 -> #DIV/0! | C35: =AVERAGE(D35:AH35) -> #DIV/0! | D35: =D34/D27 -> #DIV/0!
A36: T/O(ボーナス+リアルマネーの合計) / Total bet (Real+Bonus) | B36: =SUM(D36:AH36) -> 0 | C36: =AVERAGE(D36:AH36) -> 0 | D36: =D34+D43 -> 0
A37: 勝利金(リアルのみ) / Winning amt (Real) | B37: =SUM(D37:AH37) -> 0 | C37: =AVERAGE(D37:AH37) -> #DIV/0!
A38: 勝利金(ボーナスのみ) / Winning amt (Bonus) | B38: =SUM(D38:AH38) -> 0 | C38: =AVERAGE(D38:AH38) -> 0 | D38: 0
A39: 勝利金(ボーナス+リアルマネーの合計) / Winning (Bonus+Real) | B39: =SUM(D39:AH39) -> 0 | C39: =AVERAGE(D39:AH39) -> 0 | D39: =D38+D37 -> 0
A40: リアルマネー残高 / Real Money Balance | B40: =LOOKUP(9^9, C40:AH40) -> #N/A | C40: =AVERAGE(D40:AH40) -> #DIV/0!
...

Sheet Whitelist
A1: Whitelist TG ID
A2: 7996872876 | B2: Tom
A3: -1003439327565 | B3: Sloten group chat | D3: -1003439327565 | E3: Sloten group chat

Sheet KPI_PDF_SENT_LOG_DAILY_SLOTEN
A1: Timestamp | B1: Sheet | C1: D-2 | D1: D-1 | E1: File ID | F1: File Name | G1: Recipients (valid) | H1: Status | I1: Invalid IDs skipped | J1: Fail details | K1: DebugTrace
A2: 46041.158 | B2: 202601 | C2: 46053 | D2: 1R4lCeHlxj4UeBFGJD21NtTPqswxU56Ke | E2: 2026-01-31 Daily KPI Report.pdf | F2: 1 | G2: OK
A3: 46041.172 | B3: 202601 | C3: 46040 | D3: 46041 | E3: 1XCrsxtmQu5jddBr9OF8ngeJG0vkgaK4J | F3: 2026-01-19 Daily KPI Report.pdf | G3: 1 | H3: OK
A4: 46041.221 | B4: 46040 | C4: 1IpRiRZ56nupYl7OEEsxzPsR2bvZnrJTt | D4: 2026-01-18 Daily KPI Report.pdf | E4: 1 | F4: OK
A5: 46041.222 | B5: 46040 | C5: 1gUpG7TH2DPdMZlqq1rIDyORZMdn1s1gf | D5: 2026-01-18 Daily KPI Report.pdf | E5: 1 | F5: OK
A6: 46041.525 | B6: 202601 | C6: 46040 | D6: 46039 | E6: 142X_XeMD7P1tXFRVELlXTvGh-5oTAmhE | F6: 2026-01-18 Daily KPI Report.pdf | G6: 1 | H6: OK
A7: 46041.199 | B7: 202601 | C7: 46039 | D7: 46040 | E7: 1wPOmcg35j-k9IugWWD6O6QchU5z68TaY | F7: 2026-01-18 Daily KPI Report.pdf | G7: 1 | H7: OK
A8: 46041.22 | B8: 202601 | C8: 46052 | D8: 46053 | E8: 1EhzSvHG5Aqvt6RfgY_JTpVrtw0W8mtAH | F8: 2026-01-31 Daily KPI Report.pdf | G8: 1 | H8: OK
A9: 46041.228 | B9: 202601 | C9: 46039 | D9: 46040 | E9: 1-vNTt1qtA5z4KUXh3BU1lH-gfiBLuqro | F9: 2026-01-18 Daily KPI Report.pdf | G9: 1 | H9: OK | K9: Registered users: row=4 via=key-exact hit="登録人数" || Registered FTD+ users: row=18 via=key-exact hit="今月登録のftd以降ユーザー数" || Registered FTD+ ratio: row=19 via=key-exact hit="今月登録ftd以降ユーザー割合" || Registered active users: row=20 via=key-exact hit="今月登録のアクティブユーザー数" || Previous-month registered active users: row=21 via=key-exact hit="前月登録のアクティブユーザー数" || Total deposit amount: row=27 via=key-exact hit="総入金額 / total dp amt" || Active players (Unique): row=26 via=key-exact hit="アクティブプレイ人数（ユニーク）" || Average deposit amount (Unique user): row=29 via=key-exact hit="平均入金額(ユニークユーザー) / ave dp amt (unique user)" || Total withdrawal amount: row=32 via=key-exact hit="総出金額 / total wd amt" || Turnover (Real + Bonus): row=36 via=key-exact hit="t/o(ボーナス+リアルマネーの合計) / total bet (real+bonus)" || RTP: row=42 via=key-exact hit="rtp" || GGR: row=45 via=key-exact hit="ggr" || Deposit–Withdrawal difference: row=48 via=key-exact hit="入出金差分"
A10: 46041.24 | B10: 202601 | C10: 46039 | D10: 46040 | E10: 1Pje_amYyg5hMKcetASAP8A849nON9m0t | F10: 2026-01-18 Daily KPI Report.pdf | G10: 1 | H10: OK | K10: Registered users: row=4 via=key-exact hit="登録人数" || Registered FTD+ users: row=18 via=key-exact hit="今月登録のftd以降ユーザー数" || Registered FTD+ ratio: row=19 via=key-exact hit="今月登録ftd以降ユーザー割合" || Registered active users: row=20 via=key-exact hit="今月登録のアクティブユーザー数" || Previous-month registered active users: row=21 via=key-exact hit="前月登録のアクティブユーザー数" || Total deposit amount: row=27 via=key-exact hit="総入金額 / total dp amt" || Active players (Unique): row=26 via=key-exact hit="アクティブプレイ人数（ユニーク）" || Average deposit amount (Unique user): row=29 via=key-exact hit="平均入金額(ユニークユーザー) / ave dp amt (unique user)" || Total withdrawal amount: row=32 via=key-exact hit="総出金額 / total wd amt" || Turnover (Real + Bonus): row=36 via=key-exact hit="t/o(ボーナス+リアルマネーの合計) / total bet (real+bonus)" || RTP: row=42 via=key-exact hit="rtp" || GGR: row=45 via=key-exact hit="ggr" || Deposit–Withdrawal difference: row=48 via=key-exact hit="入出金差分"
A11: 46041.241 | B11: 202601 | C11: 46039 | D11: 46040 | E11: 1N4eDELY4S24tbxz5vbiPwG3-OobIi8vR | F11: 2026-01-18 Daily KPI Report.pdf | G11: 2 | H11: OK | K11: Registered users: row=4 via=key-exact hit="登録人数" || Registered FTD+ users: row=18 via=key-exact hit="今月登録のftd以降ユーザー数" || Registered FTD+ ratio: row=19 via=key-exact hit="今月登録ftd以降ユーザー割合" || Registered active users: row=20 via=key-exact hit="今月登録のアクティブユーザー数" || Previous-month registered active users: row=21 via=key-exact hit="前月登録のアクティブユーザー数" || Total deposit amount: row=27 via=key-exact hit="総入金額 / total dp amt" || Active players (Unique): row=26 via=key-exact hit="アクティブプレイ人数（ユニーク）" || Average deposit amount (Unique user): row=29 via=key-exact hit="平均入金額(ユニークユーザー) / ave dp amt (unique user)" || Total withdrawal amount: row=32 via=key-exact hit="総出金額 / total wd amt" || Turnover (Real + Bonus): row=36 via=key-exact hit="t/o(ボーナス+リアルマネーの合計) / total bet (real+bonus)" || RTP: row=42 via=key-exact hit="rtp" || GGR: row=45 via=key-exact hit="ggr" || Deposit–Withdrawal difference: row=48 via=key-exact hit="入出金差分"
A12: 46041.357 | B12: 202601 | C12: 46039 | D12: 46040 | E12: 1lIGNW0GUB_xxI0N0fEm50mmZLRshO2F9 | F12: 2026-01-18 Daily KPI Report.pdf | G12: 2 | H12: OK | K12: Registered users: row=4 via=key-exact hit="登録人数" || Registered FTD+ users: row=18 via=key-exact hit="今月登録のftd以降ユーザー数" || Registered FTD+ ratio: row=19 via=key-exact hit="今月登録ftd以降ユーザー割合" || Registered active users: row=20 via=key-exact hit="今月登録のアクティブユーザー数" || Previous-month registered active users: row=21 via=key-exact hit="前月登録のアクティブユーザー数" || Total deposit amount: row=27 via=key-exact hit="総入金額 / total dp amt" || Active players (Unique): row=26 via=key-exact hit="アクティブプレイ人数（ユニーク）" || Average deposit amount (Unique user): row=29 via=key-exact hit="平均入金額(ユニークユーザー) / ave dp amt (unique user)" || Total withdrawal amount: row=32 via=key-exact hit="総出金額 / total wd amt" || Turnover (Real + Bonus): row=36 via=key-exact hit="t/o(ボーナス+リアルマネーの合計) / total bet (real+bonus)" || RTP: row=42 via=key-exact hit="rtp" || GGR: row=45 via=key-exact hit="ggr" || Deposit–Withdrawal difference: row=48 via=key-exact hit="入出金差分"
A13: 46042.357 | B13: 202601 | C13: 46040 | D13: 46041 | E13: 1u10zaSTQG43ADjjzBJ7Af53G74B0aW0G | F13: 2026-01-19 Daily KPI Report.pdf | G13: 2 | H13: OK | K13: Registered users: row=4 via=key-exact hit="登録人数" || Registered FTD+ users: row=18 via=key-exact hit="今月登録のftd以降ユーザー数" || Registered FTD+ ratio: row=19 via=key-exact hit="今月登録ftd以降ユーザー割合" || Registered active users: row=20 via=key-exact hit="今月登録のアクティブユーザー数" || Previous-month registered active users: row=21 via=key-exact hit="前月登録のアクティブユーザー数" || Total deposit amount: row=27 via=key-exact hit="総入金額 / total dp amt" || Active players (Unique): row=26 via=key-exact hit="アクティブプレイ人数（ユニーク）" || Average deposit amount (Unique user): row=29 via=key-exact hit="平均入金額(ユニークユーザー) / ave dp amt (unique user)" || Total withdrawal amount: row=32 via=key-exact hit="総出金額 / total wd amt" || Turnover (Real + Bonus): row=36 via=key-exact hit="t/o(ボーナス+リアルマネーの合計) / total bet (real+bonus)" || RTP: row=42 via=key-exact hit="rtp" || GGR: row=45 via=key-exact hit="ggr" || Deposit–Withdrawal difference: row=48 via=key-exact hit="入出金差分"
A14: 46043.357 | B14: 202601 | C14: 46041 | D14: 46042 | E14: 1hVrVYMFb0ozeXgj5zNgROyoJDe1i6ODM | F14: 2026-01-20 Daily KPI Report.pdf | G14: 2 | H14: OK | K14: Registered users: row=4 via=key-exact hit="登録人数" || Registered FTD+ users: row=18 via=key-exact hit="今月登録のftd以降ユーザー数" || Registered FTD+ ratio: row=19 via=key-exact hit="今月登録ftd以降ユーザー割合" || Registered active users: row=20 via=key-exact hit="今月登録のアクティブユーザー数" || Previous-month registered active users: row=21 via=key-exact hit="前月登録のアクティブユーザー数" || Total deposit amount: row=27 via=key-exact hit="総入金額 / total dp amt" || Active players (Unique): row=26 via=key-exact hit="アクティブプレイ人数（ユニーク）" || Average deposit amount (Unique user): row=29 via=key-exact hit="平均入金額(ユニークユーザー) / ave dp amt (unique user)" || Total withdrawal amount: row=32 via=key-exact hit="総出金額 / total wd amt" || Turnover (Real + Bonus): row=36 via=key-exact hit="t/o(ボーナス+リアルマネーの合計) / total bet (real+bonus)" || RTP: row=42 via=key-exact hit="rtp" || GGR: row=45 via=key-exact hit="ggr" || Deposit–Withdrawal difference: row=48 via=key-exact hit="入出金差分"
A15: 46044.357 | B15: 202601 | C15: 46042 | D15: 46043 | E15: 1x4zyqgRegE2v6UQvAbGsST-xF9YqTEvu | F15: 2026-01-21 Daily KPI Report.pdf | G15: 2 | H15: OK | K15: Registered users: row=4 via=key-exact hit="登録人数" || Registered FTD+ users: row=18 via=key-exact hit="今月登録のftd以降ユーザー数" || Registered FTD+ ratio: row=19 via=key-exact hit="今月登録ftd以降ユーザー割合" || Registered active users: row=20 via=key-exact hit="今月登録のアクティブユーザー数" || Previous-month registered active users: row=21 via=key-exact hit="前月登録のアクティブユーザー数" || Total deposit amount: row=27 via=key-exact hit="総入金額 / total dp amt" || Active players (Unique): row=26 via=key-exact hit="アクティブプレイ人数（ユニーク）" || Average deposit amount (Unique user): row=29 via=key-exact hit="平均入金額(ユニークユーザー) / ave dp amt (unique user)" || Total withdrawal amount: row=32 via=key-exact hit="総出金額 / total wd amt" || Turnover (Real + Bonus): row=36 via=key-exact hit="t/o(ボーナス+リアルマネーの合計) / total bet (real+bonus)" || RTP: row=42 via=key-exact hit="rtp" || GGR: row=45 via=key-exact hit="ggr" || Deposit–Withdrawal difference: row=48 via=key-exact hit="入出金差分"
A16: 46045.357 | B16: 202601 | C16: 46043 | D16: 46044 | E16: 1c1T3SCE53nyVtZ8xQc9xVtgfNFX-35IX | F16: 2026-01-22 Daily KPI Report.pdf | G16: 2 | H16: OK | K16: Registered users: row=4 via=key-exact hit="登録人数" || Registered FTD+ users: row=18 via=key-exact hit="今月登録のftd以降ユーザー数" || Registered FTD+ ratio: row=19 via=key-exact hit="今月登録ftd以降ユーザー割合" || Registered active users: row=20 via=key-exact hit="今月登録のアクティブユーザー数" || Previous-month registered active users: row=21 via=key-exact hit="前月登録のアクティブユーザー数" || Total deposit amount: row=27 via=key-exact hit="総入金額 / total dp amt" || Active players (Unique): row=26 via=key-exact hit="アクティブプレイ人数（ユニーク）" || Average deposit amount (Unique user): row=29 via=key-exact hit="平均入金額(ユニークユーザー) / ave dp amt (unique user)" || Total withdrawal amount: row=32 via=key-exact hit="総出金額 / total wd amt" || Turnover (Real + Bonus): row=36 via=key-exact hit="t/o(ボーナス+リアルマネーの合計) / total bet (real+bonus)" || RTP: row=42 via=key-exact hit="rtp" || GGR: row=45 via=key-exact hit="ggr" || Deposit–Withdrawal difference: row=48 via=key-exact hit="入出金差分"
A17: 46046.357 | B17: 202601 | C17: 46044 | D17: 46045 | E17: 1goxBeR12v1I5iZYZg78s_wY0DnmJ5cyV | F17: 2026-01-23 Daily KPI Report.pdf | G17: 2 | H17: OK | K17: Registered users: row=4 via=key-exact hit="登録人数" || Registered FTD+ users: row=18 via=key-exact hit="今月登録のftd以降ユーザー数" || Registered FTD+ ratio: row=19 via=key-exact hit="今月登録ftd以降ユーザー割合" || Registered active users: row=20 via=key-exact hit="今月登録のアクティブユーザー数" || Previous-month registered active users: row=21 via=key-exact hit="前月登録のアクティブユーザー数" || Total deposit amount: row=27 via=key-exact hit="総入金額 / total dp amt" || Active players (Unique): row=26 via=key-exact hit="アクティブプレイ人数（ユニーク）" || Average deposit amount (Unique user): row=29 via=key-exact hit="平均入金額(ユニークユーザー) / ave dp amt (unique user)" || Total withdrawal amount: row=32 via=key-exact hit="総出金額 / total wd amt" || Turnover (Real + Bonus): row=36 via=key-exact hit="t/o(ボーナス+リアルマネーの合計) / total bet (real+bonus)" || RTP: row=42 via=key-exact hit="rtp" || GGR: row=45 via=key-exact hit="ggr" || Deposit–Withdrawal difference: row=48 via=key-exact hit="入出金差分"
A18: 46047.357 | B18: 202601 | C18: 46045 | D18: 46046 | E18: 1DzpejcOery9ssV4rfuKFWg8__a_1oJHD | F18: 2026-01-24 Daily KPI Report.pdf | G18: 2 | H18: OK | K18: Registered users: row=4 via=key-exact hit="登録人数" || Registered FTD+ users: row=18 via=key-exact hit="今月登録のftd以降ユーザー数" || Registered FTD+ ratio: row=19 via=key-exact hit="今月登録ftd以降ユーザー割合" || Registered active users: row=20 via=key-exact hit="今月登録のアクティブユーザー数" || Previous-month registered active users: row=21 via=key-exact hit="前月登録のアクティブユーザー数" || Total deposit amount: row=27 via=key-exact hit="総入金額 / total dp amt" || Active players (Unique): row=26 via=key-exact hit="アクティブプレイ人数（ユニーク）" || Average deposit amount (Unique user): row=29 via=key-exact hit="平均入金額(ユニークユーザー) / ave dp amt (unique user)" || Total withdrawal amount: row=32 via=key-exact hit="総出金額 / total wd amt" || Turnover (Real + Bonus): row=36 via=key-exact hit="t/o(ボーナス+リアルマネーの合計) / total bet (real+bonus)" || RTP: row=42 via=key-exact hit="rtp" || GGR: row=45 via=key-exact hit="ggr" || Deposit–Withdrawal difference: row=48 via=key-exact hit="入出金差分"
A19: 46048.357 | B19: 202601 | C19: 46046 | D19: 46047 | E19: 1kabosH9lUonf5gNibVrXBbw__Xa6hTN6 | F19: 2026-01-25 Daily KPI Report.pdf | G19: 2 | H19: OK | K19: Registered users: row=4 via=key-exact hit="登録人数" || Registered FTD+ users: row=18 via=key-exact hit="今月登録のftd以降ユーザー数" || Registered FTD+ ratio: row=19 via=key-exact hit="今月登録ftd以降ユーザー割合" || Registered active users: row=20 via=key-exact hit="今月登録のアクティブユーザー数" || Previous-month registered active users: row=21 via=key-exact hit="前月登録のアクティブユーザー数" || Total deposit amount: row=27 via=key-exact hit="総入金額 / total dp amt" || Active players (Unique): row=26 via=key-exact hit="アクティブプレイ人数（ユニーク）" || Average deposit amount (Unique user): row=29 via=key-exact hit="平均入金額(ユニークユーザー) / ave dp amt (unique user)" || Total withdrawal amount: row=32 via=key-exact hit="総出金額 / total wd amt" || Turnover (Real + Bonus): row=36 via=key-exact hit="t/o(ボーナス+リアルマネーの合計) / total bet (real+bonus)" || RTP: row=42 via=key-exact hit="rtp" || GGR: row=45 via=key-exact hit="ggr" || Deposit–Withdrawal difference: row=48 via=key-exact hit="入出金差分"
A20: 46049.357 | B20: 202601 | C20: 46047 | D20: 46048 | E20: 18TOIidWQX1_xW-bUgB7hPKhzzEpAzH8P | F20: 2026-01-26 Daily KPI Report.pdf | G20: 2 | H20: OK | K20: Registered users: row=4 via=key-exact hit="登録人数" || Registered FTD+ users: row=18 via=key-exact hit="今月登録のftd以降ユーザー数" || Registered FTD+ ratio: row=19 via=key-exact hit="今月登録ftd以降ユーザー割合" || Registered active users: row=20 via=key-exact hit="今月登録のアクティブユーザー数" || Previous-month registered active users: row=21 via=key-exact hit="前月登録のアクティブユーザー数" || Total deposit amount: row=27 via=key-exact hit="総入金額 / total dp amt" || Active players (Unique): row=26 via=key-exact hit="アクティブプレイ人数（ユニーク）" || Average deposit amount (Unique user): row=29 via=key-exact hit="平均入金額(ユニークユーザー) / ave dp amt (unique user)" || Total withdrawal amount: row=32 via=key-exact hit="総出金額 / total wd amt" || Turnover (Real + Bonus): row=36 via=key-exact hit="t/o(ボーナス+リアルマネーの合計) / total bet (real+bonus)" || RTP: row=42 via=key-exact hit="rtp" || GGR: row=45 via=key-exact hit="ggr" || Deposit–Withdrawal difference: row=48 via=key-exact hit="入出金差分"
... A22: 46051.357 | B22: 202601 | C22: 46049 | D22: 46050 | E22: 1K_HlUmHYna2NPQXUoj3JL4Hy46gn0Jza | F22: 2026-01-28 Daily KPI Report.pdf | G22: 2 | H22: OK | K22: Registered users: row=4 via=key-exact hit="登録人数" || Registered FTD+ users: row=18 via=key-exact hit="今月登録のftd以降ユーザー数" || Registered FTD+ ratio: row=19 via=key-exact hit="今月登録ftd以降ユーザー割合" || Registered active users: row=20 via=key-exact hit="今月登録のアクティブユーザー数" || Previous-month registered active users: row=21 via=key-exact hit="前月登録のアクティブユーザー数" || Total deposit amount: row=27 via=key-exact hit="総入金額 / total dp amt" || Active players (Unique): row=26 via=key-exact hit="アクティブプレイ人数（ユニーク）" || Average deposit amount (Unique user): row=29 via=key-exact hit="平均入金額(ユニークユーザー) / ave dp amt (unique user)" || Total withdrawal amount: row=32 via=key-exact hit="総出金額 / total wd amt" || Turnover (Real + Bonus): row=36 via=key-exact hit="t/o(ボーナス+リアルマネーの合計) / total bet (real+bonus)" || RTP: row=42 via=key-exact hit="rtp" || GGR: row=45 via=key-exact hit="ggr" || Deposit–Withdrawal difference: row=48 via=key-exact hit="入出金差分"

Sheet KPI_PDF_SENT_LOG_MONTHLY_SLOTEN
A1: Timestamp | B1: Sheet | C1: TOTAL Label | D1: M-1 | E1: M | F1: File ID | G1: File Name | H1: Recipients (valid) | I1: Status | J1: Invalid IDs skipped | K1: Fail details | L1: DebugTrace
A2: 46041.204 | B2: 全期間集計_TOTAL | C2: TOTAL | D2: 202512 | E2: 202601 | F2: 1Xg3wpPtq0Hrj5iyt5jEdnsDVZBXN2G22 | G2: 202601 Monthly KPI Report.pdf | H2: 1 | I2: OK
A3: 46041.21 | B3: 全期間集計_TOTAL | C3: TOTAL | D3: 202512 | E3: 202601 | F3: 1LVa-xXA4tqJ4WNRSCbGVjMxvm5yZG7P- | G3: 202601 Monthly KPI Report.pdf | H3: 1 | I3: OK
